Workbook

Sheet train_raw
A1: PassengerId | B1: Survived | C1: Pclass | D1: Name | E1: Sex | F1: Age | G1: SibSp | H1: Parch | I1: Ticket | J1: Fare | K1: Cabin | L1: Embarked
A2: 1 | B2: 0 | C2: 3 | D2: Braund, Mr. Owen Harris | E2: male | F2: 22 | G2: 1 | H2: 0 | I2: A/5 21171 | J2: 7.25 | L2: S
A3: 2 | B3: 1 | C3: 1 | D3: Cumings, Mrs. John Bradley (Florence Briggs Thayer) | E3: female | F3: 38 | G3: 1 | H3: 0 | I3: PC 17599 | J3: 71.2833 | K3: C85 | L3: C
A4: 3 | B4: 1 | C4: 3 | D4: Heikkinen, Miss. Laina | E4: female | F4: 26 | G4: 0 | H4: 0 | I4: STON/O2. 3101282 | J4: 7.925 | L4: S
A5: 4 | B5: 1 | C5: 1 | D5: Futrelle, Mrs. Jacques Heath (Lily May Peel) | E5: female | F5: 35 | G5: 1 | H5: 0 | I5: 113803 | J5: 53.1 | K5: C123 | L5: S
A6: 5 | B6: 0 | C6: 3 | D6: Allen, Mr. William Henry | E6: male | F6: 35 | G6: 0 | H6: 0 | I6: 373450 | J6: 8.05 | L6: S
A7: 6 | B7: 0 | C7: 3 | D7: Moran, Mr. James | E7: male | F7: \N | G7: 0 | H7: 0 | I7: 330877 | J7: 8.4583 | L7: Q
A8: 7 | B8: 0 | C8: 1 | D8: McCarthy, Mr. Timothy J | E8: male | F8: 54 | G8: 0 | H8: 0 | I8: 17463 | J8: 51.8625 | K8: E46 | L8: S
A9: 8 | B9: 0 | C9: 3 | D9: Palsson, Master. Gosta Leonard | E9: male | F9: 2 | G9: 3 | H9: 1 | I9: 349909 | J9: 21.075 | L9: S
A10: 9 | B10: 1 | C10: 3 | D10: Johnson, Mrs. Oscar W (Elisabeth Vilhelmina Berg) | E10: female | F10: 27 | G10: 0 | H10: 2 | I10: 347742 | J10: 11.1333 | L10: S
A11: 10 | B11: 1 | C11: 2 | D11: Nasser, Mrs. Nicholas (Adele Achem) | E11: female | F11: 14 | G11: 1 | H11: 0 | I11: 237736 | J11: 30.0708 | L11: C
A12: 11 | B12: 1 | C12: 3 | D12: Sandstrom, Miss. Marguerite Rut | E12: female | F12: 4 | G12: 1 | H12: 1 | I12: PP 9549 | J12: 16.7 | K12: G6 | L12: S
A13: 12 | B13: 1 | C13: 1 | D13: Bonnell, Miss. Elizabeth | E13: female | F13: 58 | G13: 0 | H13: 0 | I13: 113783 | J13: 26.55 | K13: C103 | L13: S
A14: 13 | B14: 0 | C14: 3 | D14: Saundercock, Mr. William Henry | E14: male | F14: 20 | G14: 0 | H14: 0 | I14: A/5. 2151 | J14: 8.05 | L14: S
A15: 14 | B15: 0 | C15: 3 | D15: Andersson, Mr. Anders Johan | E15: male | F15: 39 | G15: 1 | H15: 5 | I15: 347082 | J15: 31.275 | L15: S
A16: 15 | B16: 0 | C16: 3 | D16: Vestrom, Miss. Hulda Amanda Adolfina | E16: female | F16: 14 | G16: 0 | H16: 0 | I16: 350406 | J16: 7.8542 | L16: S
A17: 16 | B17: 1 | C17: 2 | D17: Hewlett, Mrs. (Mary D Kingcome) | E17: female | F17: 55 | G17: 0 | H17: 0 | I17: 248706 | J17: 16 | L17: S
A18: 17 | B18: 0 | C18: 3 | D18: Rice, Master. Eugene | E18: male | F18: 2 | G18: 4 | H18: 1 | I18: 382652 | J18: 29.125 | L18: Q
A19: 18 | B19: 1 | C19: 2 | D19: Williams, Mr. Charles Eugene | E19: male | F19: \N | G19: 0 | H19: 0 | I19: 244373 | J19: 13 | L19: S
A20: 19 | B20: 0 | C20: 3 | D20: Vander Planke, Mrs. Julius (Emelia Maria Vandemoortele) | E20: female | F20: 31 | G20: 1 | H20: 0 | I20: 345763 | J20: 18 | L20: S
A21: 20 | B21: 1 | C21: 3 | D21: Masselmani, Mrs. Fatima | E21: female | F21: \N | G21: 0 | H21: 0 | I21: 2649 | J21: 7.225 | L21: C
A22: 21 | B22: 0 | C22: 2 | D22: Fynney, Mr. Joseph J | E22: male | F22: 35 | G22: 0 | H22: 0 | I22: 239865 | J22: 26 | L22: S
A23: 22 | B23: 1 | C23: 2 | D23: Beesley, Mr. Lawrence | E23: male | F23: 34 | G23: 0 | H23: 0 | I23: 248698 | J23: 13 | K23: D56 | L23: S
A24: 23 | B24: 1 | C24: 3 | D24: McGowan, Miss. Anna "Annie" | E24: female | F24: 15 | G24: 0 | H24: 0 | I24: 330923 | J24: 8.0292 | L24: Q
A25: 24 | B25: 1 | C25: 1 | D25: Sloper, Mr. William Thompson | E25: male | F25: 28 | G25: 0 | H25: 0 | I25: 113788 | J25: 35.5 | K25: A6 | L25: S
A26: 25 | B26: 0 | C26: 3 | D26: Palsson, Miss. Torborg Danira | E26: female | F26: 8 | G26: 3 | H26: 1 | I26: 349909 | J26: 21.075 | L26: S
A27: 26 | B27: 1 | C27: 3 | D27: Asplund, Mrs. Carl Oscar (Selma Augusta Emilia Johansson) | E27: female | F27: 38 | G27: 1 | H27: 5 | I27: 347077 | J27: 31.3875 | L27: S
A28: 27 | B28: 0 | C28: 3 | D28: Emir, Mr. Farred Chehab | E28: male | F28: \N | G28: 0 | H28: 0 | I28: 2631 | J28: 7.225 | L28: C
A29: 28 | B29: 0 | C29: 1 | D29: Fortune, Mr. Charles Alexander | E29: male | F29: 19 | G29: 3 | H29: 2 | I29: 19950 | J29: 263 | K29: C23 C25 C27 | L29: S
A30: 29 | B30: 1 | C30: 3 | D30: O'Dwyer, Miss. Ellen "Nellie" | E30: female | F30: \N | G30: 0 | H30: 0 | I30: 330959 | J30: 7.8792 | L30: Q
A31: 30 | B31: 0 | C31: 3 | D31: Todoroff, Mr. Lalio | E31: male | F31: \N | G31: 0 | H31: 0 | I31: 349216 | J31: 7.8958 | L31: S
A32: 31 | B32: 0 | C32: 1 | D32: Uruchurtu, Don. Manuel E | E32: male | F32: 40 | G32: 0 | H32: 0 | I32: PC 17601 | J32: 27.7208 | L32: C
A33: 32 | B33: 1 | C33: 1 | D33: Spencer, Mrs. William Augustus (Marie Eugenie) | E33: female | F33: \N | G33: 1 | H33: 0 | I33: PC 17569 | J33: 146.5208 | K33: B78 | L33: C
A34: 33 | B34: 1 | C34: 3 | D34: Glynn, Miss. Mary Agatha | E34: female | F34: \N | G34: 0 | H34: 0 | I34: 335677 | J34: 7.75 | L34: Q
A35: 34 | B35: 0 | C35: 2 | D35: Wheadon, Mr. Edward H | E35: male | F35: 66 | G35: 0 | H35: 0 | I35: C.A. 24579 | J35: 10.5 | L35: S
A36: 35 | B36: 0 | C36: 1 | D36: Meyer, Mr. Edgar Joseph | E36: male | F36: 28 | G36: 1 | H36: 0 | I36: PC 17604 | J36: 82.1708 | L36: C
A37: 36 | B37: 0 | C37: 1 | D37: Holverson, Mr. Alexander Oskar | E37: male | F37: 42 | G37: 1 | H37: 0 | I37: 113789 | J37: 52 | L37: S
A38: 37 | B38: 1 | C38: 3 | D38: Mamee, Mr. Hanna | E38: male | F38: \N | G38: 0 | H38: 0 | I38: 2677 | J38: 7.2292 | L38: C
A39: 38 | B39: 0 | C39: 3 | D39: Cann, Mr. Ernest Charles | E39: male | F39: 21 | G39: 0 | H39: 0 | I39: A./5. 2152 | J39: 8.05 | L39: S
A40: 39 | B40: 0 | C40: 3 | D40: Vander Planke, Miss. Augusta Maria | E40: female | F40: 18 | G40: 2 | H40: 0 | I40: 345764 | J40: 18 | L40: S
...

Sheet Worksheet
A1: PassengerId | B1: Survived | C1: Pclass | D1: Last_Name | E1: First_Name | F1: Title | G1: Gender | H1: Age | I1: Age_Group | J1: SibSp | K1: Parch | L1: Family_Size | M1: Survival_Status | N1: Family_Category | O1: Ticket | P1: Fare | Q1: Fare Fraction | R1: Cabin | S1: Embarked | T1: Embark_Point
A2: 1 | B2: 0 | C2: 3 | D2: Braund | E2: Owen Harris | F2: Mr | G2: =_xlfn.XLOOKUP(F2,notes!$B$12:$B$18,notes!$C$12:$C$18,"Unknown") -> Male | H2: 22 | I2: =_xlfn.XLOOKUP(H2,notes!$B$4:$B$8,notes!$C$4:$C$8,"Invalid",-1) -> Adult | J2: 1 | K2: 0 | L2: =(J2+K2)+1 -> 2 | M2: =IF(B2=1,"Survived","Not Survived") -> Not Survived | N2: =_xlfn.XLOOKUP(L2,notes!$B$28:$B$30,notes!$C$28:$C$30,"Unknown",-1) -> Small Family | O2: A/5 21171 | P2: 7.25 | Q2: =IF(P2>=50,"High",IF(P2>=10,"Mid",IF(P2<10,"Low","invalid"))) -> Low | R2: Unknown | S2: S | T2: =IF(S2="Q","Queenstown",IF(S2="C","Cherbourg",IF(S2="S","Southampton","Unknown"))) -> Southampton
A3: 2 | B3: 1 | C3: 1 | D3: Cumings | E3: John Bradley (Florence Briggs Thayer) | F3: Mrs | G3: =_xlfn.XLOOKUP(F3,notes!$B$12:$B$18,notes!$C$12:$C$18,"Unknown") -> Female | H3: 38 | I3: =_xlfn.XLOOKUP(H3,notes!$B$4:$B$8,notes!$C$4:$C$8,"Invalid",-1) -> Adult | J3: 1 | K3: 0 | L3: =(J3+K3)+1 -> 2 | M3: =IF(B3=1,"Survived","Not Survived") -> Survived | N3: =_xlfn.XLOOKUP(L3,notes!$B$28:$B$30,notes!$C$28:$C$30,"Unknown",-1) -> Small Family | O3: PC 17599 | P3: 71.2833 | Q3: =IF(P3>=50,"High",IF(P3>=10,"Mid",IF(P3<10,"Low","invalid"))) -> High | R3: C85 | S3: C | T3: =IF(S3="Q","Queenstown",IF(S3="C","Cherbourg",IF(S3="S","Southampton","Unknown"))) -> Cherbourg
A4: 3 | B4: 1 | C4: 3 | D4: Heikkinen | E4: Laina | F4: Miss | G4: =_xlfn.XLOOKUP(F4,notes!$B$12:$B$18,notes!$C$12:$C$18,"Unknown") -> Female | H4: 26 | I4: =_xlfn.XLOOKUP(H4,notes!$B$4:$B$8,notes!$C$4:$C$8,"Invalid",-1) -> Adult | J4: 0 | K4: 0 | L4: =(J4+K4)+1 -> 1 | M4: =IF(B4=1,"Survived","Not Survived") -> Survived | N4: =_xlfn.XLOOKUP(L4,notes!$B$28:$B$30,notes!$C$28:$C$30,"Unknown",-1) -> Alone | O4: STON/O2. 3101282 | P4: 7.925 | Q4: =IF(P4>=50,"High",IF(P4>=10,"Mid",IF(P4<10,"Low","invalid"))) -> Low | R4: Unknown | S4: S | T4: =IF(S4="Q","Queenstown",IF(S4="C","Cherbourg",IF(S4="S","Southampton","Unknown"))) -> Southampton
A5: 4 | B5: 1 | C5: 1 | D5: Futrelle | E5: Jacques Heath (Lily May Peel) | F5: Mrs | G5: =_xlfn.XLOOKUP(F5,notes!$B$12:$B$18,notes!$C$12:$C$18,"Unknown") -> Female | H5: 35 | I5: =_xlfn.XLOOKUP(H5,notes!$B$4:$B$8,notes!$C$4:$C$8,"Invalid",-1) -> Adult | J5: 1 | K5: 0 | L5: =(J5+K5)+1 -> 2 | M5: =IF(B5=1,"Survived","Not Survived") -> Survived | N5: =_xlfn.XLOOKUP(L5,notes!$B$28:$B$30,notes!$C$28:$C$30,"Unknown",-1) -> Small Family | O5: 113803 | P5: 53.1 | Q5: =IF(P5>=50,"High",IF(P5>=10,"Mid",IF(P5<10,"Low","invalid"))) -> High | R5: C123 | S5: S | T5: =IF(S5="Q","Queenstown",IF(S5="C","Cherbourg",IF(S5="S","Southampton","Unknown"))) -> Southampton
A6: 5 | B6: 0 | C6: 3 | D6: Allen | E6: William Henry | F6: Mr | G6: =_xlfn.XLOOKUP(F6,notes!$B$12:$B$18,notes!$C$12:$C$18,"Unknown") -> Male | H6: 35 | I6: =_xlfn.XLOOKUP(H6,notes!$B$4:$B$8,notes!$C$4:$C$8,"Invalid",-1) -> Adult | J6: 0 | K6: 0 | L6: =(J6+K6)+1 -> 1 | M6: =IF(B6=1,"Survived","Not Survived") -> Not Survived | N6: =_xlfn.XLOOKUP(L6,notes!$B$28:$B$30,notes!$C$28:$C$30,"Unknown",-1) -> Alone | O6: 373450 | P6: 8.05 | Q6: =IF(P6>=50,"High",IF(P6>=10,"Mid",IF(P6<10,"Low","invalid"))) -> Low | R6: Unknown | S6: S | T6: =IF(S6="Q","Queenstown",IF(S6="C","Cherbourg",IF(S6="S","Southampton","Unknown"))) -> Southampton
A7: 6 | B7: 0 | C7: 3 | D7: Moran | E7: James | F7: Mr | G7: =_xlfn.XLOOKUP(F7,notes!$B$12:$B$18,notes!$C$12:$C$18,"Unknown") -> Male | H7: Unknown | I7: =_xlfn.XLOOKUP(H7,notes!$B$4:$B$8,notes!$C$4:$C$8,"Invalid",-1) -> Unknown | J7: 0 | K7: 0 | L7: =(J7+K7)+1 -> 1 | M7: =IF(B7=1,"Survived","Not Survived") -> Not Survived | N7: =_xlfn.XLOOKUP(L7,notes!$B$28:$B$30,notes!$C$28:$C$30,"Unknown",-1) -> Alone | O7: 330877 | P7: 8.4583 | Q7: =IF(P7>=50,"High",IF(P7>=10,"Mid",IF(P7<10,"Low","invalid"))) -> Low | R7: Unknown | S7: Q | T7: =IF(S7="Q","Queenstown",IF(S7="C","Cherbourg",IF(S7="S","Southampton","Unknown"))) -> Queenstown
A8: 7 | B8: 0 | C8: 1 | D8: McCarthy | E8: Timothy J | F8: Mr | G8: =_xlfn.XLOOKUP(F8,notes!$B$12:$B$18,notes!$C$12:$C$18,"Unknown") -> Male | H8: 54 | I8: =_xlfn.XLOOKUP(H8,notes!$B$4:$B$8,notes!$C$4:$C$8,"Invalid",-1) -> Adult | J8: 0 | K8: 0 | L8: =(J8+K8)+1 -> 1 | M8: =IF(B8=1,"Survived","Not Survived") -> Not Survived | N8: =_xlfn.XLOOKUP(L8,notes!$B$28:$B$30,notes!$C$28:$C$30,"Unknown",-1) -> Alone | O8: 17463 | P8: 51.8625 | Q8: =IF(P8>=50,"High",IF(P8>=10,"Mid",IF(P8<10,"Low","invalid"))) -> High | R8: E46 | S8: S | T8: =IF(S8="Q","Queenstown",IF(S8="C","Cherbourg",IF(S8="S","Southampton","Unknown"))) -> Southampton
A9: 8 | B9: 0 | C9: 3 | D9: Palsson | E9: Gosta Leonard | F9: Master | G9: =_xlfn.XLOOKUP(F9,notes!$B$12:$B$18,notes!$C$12:$C$18,"Unknown") -> Male | H9: 2 | I9: =_xlfn.XLOOKUP(H9,notes!$B$4:$B$8,notes!$C$4:$C$8,"Invalid",-1) -> Kid | J9: 3 | K9: 1 | L9: =(J9+K9)+1 -> 5 | M9: =IF(B9=1,"Survived","Not Survived") -> Not Survived | N9: =_xlfn.XLOOKUP(L9,notes!$B$28:$B$30,notes!$C$28:$C$30,"Unknown",-1) -> Large Family | O9: 349909 | P9: 21.075 | Q9: =IF(P9>=50,"High",IF(P9>=10,"Mid",IF(P9<10,"Low","invalid"))) -> Mid | R9: Unknown | S9: S | T9: =IF(S9="Q","Queenstown",IF(S9="C","Cherbourg",IF(S9="S","Southampton","Unknown"))) -> Southampton
A10: 9 | B10: 1 | C10: 3 | D10: Johnson | E10: Oscar W (Elisabeth Vilhelmina Berg) | F10: Mrs | G10: =_xlfn.XLOOKUP(F10,notes!$B$12:$B$18,notes!$C$12:$C$18,"Unknown") -> Female | H10: 27 | I10: =_xlfn.XLOOKUP(H10,notes!$B$4:$B$8,notes!$C$4:$C$8,"Invalid",-1) -> Adult | J10: 0 | K10: 2 | L10: =(J10+K10)+1 -> 3 | M10: =IF(B10=1,"Survived","Not Survived") -> Survived | N10: =_xlfn.XLOOKUP(L10,notes!$B$28:$B$30,notes!$C$28:$C$30,"Unknown",-1) -> Small Family | O10: 347742 | P10: 11.1333 | Q10: =IF(P10>=50,"High",IF(P10>=10,"Mid",IF(P10<10,"Low","invalid"))) -> Mid | R10: Unknown | S10: S | T10: =IF(S10="Q","Queenstown",IF(S10="C","Cherbourg",IF(S10="S","Southampton","Unknown"))) -> Southampton
A11: 10 | B11: 1 | C11: 2 | D11: Nasser | E11: Nicholas (Adele Achem) | F11: Mrs | G11: =_xlfn.XLOOKUP(F11,notes!$B$12:$B$18,notes!$C$12:$C$18,"Unknown") -> Female | H11: 14 | I11: =_xlfn.XLOOKUP(H11,notes!$B$4:$B$8,notes!$C$4:$C$8,"Invalid",-1) -> Teenager | J11: 1 | K11: 0 | L11: =(J11+K11)+1 -> 2 | M11: =IF(B11=1,"Survived","Not Survived") -> Survived | N11: =_xlfn.XLOOKUP(L11,notes!$B$28:$B$30,notes!$C$28:$C$30,"Unknown",-1) -> Small Family | O11: 237736 | P11: 30.0708 | Q11: =IF(P11>=50,"High",IF(P11>=10,"Mid",IF(P11<10,"Low","invalid"))) -> Mid | R11: Unknown | S11: C | T11: =IF(S11="Q","Queenstown",IF(S11="C","Cherbourg",IF(S11="S","Southampton","Unknown"))) -> Cherbourg
A12: 11 | B12: 1 | C12: 3 | D12: Sandstrom | E12: Marguerite Rut | F12: Miss | G12: =_xlfn.XLOOKUP(F12,notes!$B$12:$B$18,notes!$C$12:$C$18,"Unknown") -> Female | H12: 4 | I12: =_xlfn.XLOOKUP(H12,notes!$B$4:$B$8,notes!$C$4:$C$8,"Invalid",-1) -> Kid | J12: 1 | K12: 1 | L12: =(J12+K12)+1 -> 3 | M12: =IF(B12=1,"Survived","Not Survived") -> Survived | N12: =_xlfn.XLOOKUP(L12,notes!$B$28:$B$30,notes!$C$28:$C$30,"Unknown",-1) -> Small Family | O12: PP 9549 | P12: 16.7 | Q12: =IF(P12>=50,"High",IF(P12>=10,"Mid",IF(P12<10,"Low","invalid"))) -> Mid | R12: G6 | S12: S | T12: =IF(S12="Q","Queenstown",IF(S12="C","Cherbourg",IF(S12="S","Southampton","Unknown"))) -> Southampton
A13: 12 | B13: 1 | C13: 1 | D13: Bonnell | E13: Elizabeth | F13: Miss | G13: =_xlfn.XLOOKUP(F13,notes!$B$12:$B$18,notes!$C$12:$C$18,"Unknown") -> Female | H13: 58 | I13: =_xlfn.XLOOKUP(H13,notes!$B$4:$B$8,notes!$C$4:$C$8,"Invalid",-1) -> Adult | J13: 0 | K13: 0 | L13: =(J13+K13)+1 -> 1 | M13: =IF(B13=1,"Survived","Not Survived") -> Survived | N13: =_xlfn.XLOOKUP(L13,notes!$B$28:$B$30,notes!$C$28:$C$30,"Unknown",-1) -> Alone | O13: 113783 | P13: 26.55 | Q13: =IF(P13>=50,"High",IF(P13>=10,"Mid",IF(P13<10,"Low","invalid"))) -> Mid | R13: C103 | S13: S | T13: =IF(S13="Q","Queenstown",IF(S13="C","Cherbourg",IF(S13="S","Southampton","Unknown"))) -> Southampton
A14: 13 | B14: 0 | C14: 3 | D14: Saundercock | E14: William Henry | F14: Mr | G14: =_xlfn.XLOOKUP(F14,notes!$B$12:$B$18,notes!$C$12:$C$18,"Unknown") -> Male | H14: 20 | I14: =_xlfn.XLOOKUP(H14,notes!$B$4:$B$8,notes!$C$4:$C$8,"Invalid",-1) -> Adult | J14: 0 | K14: 0 | L14: =(J14+K14)+1 -> 1 | M14: =IF(B14=1,"Survived","Not Survived") -> Not Survived | N14: =_xlfn.XLOOKUP(L14,notes!$B$28:$B$30,notes!$C$28:$C$30,"Unknown",-1) -> Alone | O14: A/5. 2151 | P14: 8.05 | Q14: =IF(P14>=50,"High",IF(P14>=10,"Mid",IF(P14<10,"Low","invalid"))) -> Low | R14: Unknown | S14: S | T14: =IF(S14="Q","Queenstown",IF(S14="C","Cherbourg",IF(S14="S","Southampton","Unknown"))) -> Southampton
A15: 14 | B15: 0 | C15: 3 | D15: Andersson | E15: Anders Johan | F15: Mr | G15: =_xlfn.XLOOKUP(F15,notes!$B$12:$B$18,notes!$C$12:$C$18,"Unknown") -> Male | H15: 39 | I15: =_xlfn.XLOOKUP(H15,notes!$B$4:$B$8,notes!$C$4:$C$8,"Invalid",-1) -> Adult | J15: 1 | K15: 5 | L15: =(J15+K15)+1 -> 7 | M15: =IF(B15=1,"Survived","Not Survived") -> Not Survived | N15: =_xlfn.XLOOKUP(L15,notes!$B$28:$B$30,notes!$C$28:$C$30,"Unknown",-1) -> Large Family | O15: 347082 | P15: 31.275 | Q15: =IF(P15>=50,"High",IF(P15>=10,"Mid",IF(P15<10,"Low","invalid"))) -> Mid | R15: Unknown | S15: S | T15: =IF(S15="Q","Queenstown",IF(S15="C","Cherbourg",IF(S15="S","Southampton","Unknown"))) -> Southampton
A16: 15 | B16: 0 | C16: 3 | D16: Vestrom | E16: Hulda Amanda Adolfina | F16: Miss | G16: =_xlfn.XLOOKUP(F16,notes!$B$12:$B$18,notes!$C$12:$C$18,"Unknown") -> Female | H16: 14 | I16: =_xlfn.XLOOKUP(H16,notes!$B$4:$B$8,notes!$C$4:$C$8,"Invalid",-1) -> Teenager | J16: 0 | K16: 0 | L16: =(J16+K16)+1 -> 1 | M16: =IF(B16=1,"Survived","Not Survived") -> Not Survived | N16: =_xlfn.XLOOKUP(L16,notes!$B$28:$B$30,notes!$C$28:$C$30,"Unknown",-1) -> Alone | O16: 350406 | P16: 7.8542 | Q16: =IF(P16>=50,"High",IF(P16>=10,"Mid",IF(P16<10,"Low","invalid"))) -> Low | R16: Unknown | S16: S | T16: =IF(S16="Q","Queenstown",IF(S16="C","Cherbourg",IF(S16="S","Southampton","Unknown"))) -> Southampton
A17: 16 | B17: 1 | C17: 2 | D17: Hewlett | E17: (Mary D Kingcome) | F17: Mrs | G17: =_xlfn.XLOOKUP(F17,notes!$B$12:$B$18,notes!$C$12:$C$18,"Unknown") -> Female | H17: 55 | I17: =_xlfn.XLOOKUP(H17,notes!$B$4:$B$8,notes!$C$4:$C$8,"Invalid",-1) -> Adult | J17: 0 | K17: 0 | L17: =(J17+K17)+1 -> 1 | M17: =IF(B17=1,"Survived","Not Survived") -> Survived | N17: =_xlfn.XLOOKUP(L17,notes!$B$28:$B$30,notes!$C$28:$C$30,"Unknown",-1) -> Alone | O17: 248706 | P17: 16 | Q17: =IF(P17>=50,"High",IF(P17>=10,"Mid",IF(P17<10,"Low","invalid"))) -> Mid | R17: Unknown | S17: S | T17: =IF(S17="Q","Queenstown",IF(S17="C","Cherbourg",IF(S17="S","Southampton","Unknown"))) -> Southampton
A18: 17 | B18: 0 | C18: 3 | D18: Rice | E18: Eugene | F18: Master | G18: =_xlfn.XLOOKUP(F18,notes!$B$12:$B$18,notes!$C$12:$C$18,"Unknown") -> Male | H18: 2 | I18: =_xlfn.XLOOKUP(H18,notes!$B$4:$B$8,notes!$C$4:$C$8,"Invalid",-1) -> Kid | J18: 4 | K18: 1 | L18: =(J18+K18)+1 -> 6 | M18: =IF(B18=1,"Survived","Not Survived") -> Not Survived | N18: =_xlfn.XLOOKUP(L18,notes!$B$28:$B$30,notes!$C$28:$C$30,"Unknown",-1) -> Large Family | O18: 382652 | P18: 29.125 | Q18: =IF(P18>=50,"High",IF(P18>=10,"Mid",IF(P18<10,"Low","invalid"))) -> Mid | R18: Unknown | S18: Q | T18: =IF(S18="Q","Queenstown",IF(S18="C","Cherbourg",IF(S18="S","Southampton","Unknown"))) -> Queenstown
A19: 18 | B19: 1 | C19: 2 | D19: Williams | E19: Charles Eugene | F19: Mr | G19: =_xlfn.XLOOKUP(F19,notes!$B$12:$B$18,notes!$C$12:$C$18,"Unknown") -> Male | H19: Unknown | I19: =_xlfn.XLOOKUP(H19,notes!$B$4:$B$8,notes!$C$4:$C$8,"Invalid",-1) -> Unknown | J19: 0 | K19: 0 | L19: =(J19+K19)+1 -> 1 | M19: =IF(B19=1,"Survived","Not Survived") -> Survived | N19: =_xlfn.XLOOKUP(L19,notes!$B$28:$B$30,notes!$C$28:$C$30,"Unknown",-1) -> Alone | O19: 244373 | P19: 13 | Q19: =IF(P19>=50,"High",IF(P19>=10,"Mid",IF(P19<10,"Low","invalid"))) -> Mid | R19: Unknown | S19: S | T19: =IF(S19="Q","Queenstown",IF(S19="C","Cherbourg",IF(S19="S","Southampton","Unknown"))) -> Southampton
A20: 19 | B20: 0 | C20: 3 | D20: Vander Planke | E20: Julius (Emelia Maria Vandemoortele) | F20: Mrs | G20: =_xlfn.XLOOKUP(F20,notes!$B$12:$B$18,notes!$C$12:$C$18,"Unknown") -> Female | H20: 31 | I20: =_xlfn.XLOOKUP(H20,notes!$B$4:$B$8,notes!$C$4:$C$8,"Invalid",-1) -> Adult | J20: 1 | K20: 0 | L20: =(J20+K20)+1 -> 2 | M20: =IF(B20=1,"Survived","Not Survived") -> Not Survived | N20: =_xlfn.XLOOKUP(L20,notes!$B$28:$B$30,notes!$C$28:$C$30,"Unknown",-1) -> Small Family | O20: 345763 | P20: 18 | Q20: =IF(P20>=50,"High",IF(P20>=10,"Mid",IF(P20<10,"Low","invalid"))) -> Mid | R20: Unknown | S20: S | T20: =IF(S20="Q","Queenstown",IF(S20="C","Cherbourg",IF(S20="S","Southampton","Unknown"))) -> Southampton
A21: 20 | B21: 1 | C21: 3 | D21: Masselmani | E21: Fatima | F21: Mrs | G21: =_xlfn.XLOOKUP(F21,notes!$B$12:$B$18,notes!$C$12:$C$18,"Unknown") -> Female | H21: Unknown | I21: =_xlfn.XLOOKUP(H21,notes!$B$4:$B$8,notes!$C$4:$C$8,"Invalid",-1) -> Unknown | J21: 0 | K21: 0 | L21: =(J21+K21)+1 -> 1 | M21: =IF(B21=1,"Survived","Not Survived") -> Survived | N21: =_xlfn.XLOOKUP(L21,notes!$B$28:$B$30,notes!$C$28:$C$30,"Unknown",-1) -> Alone | O21: 2649 | P21: 7.225 | Q21: =IF(P21>=50,"High",IF(P21>=10,"Mid",IF(P21<10,"Low","invalid"))) -> Low | R21: Unknown | S21: C | T21: =IF(S21="Q","Queenstown",IF(S21="C","Cherbourg",IF(S21="S","Southampton","Unknown"))) -> Cherbourg
A22: 21 | B22: 0 | C22: 2 | D22: Fynney | E22: Joseph J | F22: Mr | G22: =_xlfn.XLOOKUP(F22,notes!$B$12:$B$18,notes!$C$12:$C$18,"Unknown") -> Male | H22: 35 | I22: =_xlfn.XLOOKUP(H22,notes!$B$4:$B$8,notes!$C$4:$C$8,"Invalid",-1) -> Adult | J22: 0 | K22: 0 | L22: =(J22+K22)+1 -> 1 | M22: =IF(B22=1,"Survived","Not Survived") -> Not Survived | N22: =_xlfn.XLOOKUP(L22,notes!$B$28:$B$30,notes!$C$28:$C$30,"Unknown",-1) -> Alone | O22: 239865 | P22: 26 | Q22: =IF(P22>=50,"High",IF(P22>=10,"Mid",IF(P22<10,"Low","invalid"))) -> Mid | R22: Unknown | S22: S | T22: =IF(S22="Q","Queenstown",IF(S22="C","Cherbourg",IF(S22="S","Southampton","Unknown"))) -> Southampton
A23: 22 | B23: 1 | C23: 2 | D23: Beesley | E23: Lawrence | F23: Mr | G23: =_xlfn.XLOOKUP(F23,notes!$B$12:$B$18,notes!$C$12:$C$18,"Unknown") -> Male | H23: 34 | I23: =_xlfn.XLOOKUP(H23,notes!$B$4:$B$8,notes!$C$4:$C$8,"Invalid",-1) -> Adult | J23: 0 | K23: 0 | L23: =(J23+K23)+1 -> 1 | M23: =IF(B23=1,"Survived","Not Survived") -> Survived | N23: =_xlfn.XLOOKUP(L23,notes!$B$28:$B$30,notes!$C$28:$C$30,"Unknown",-1) -> Alone | O23: 248698 | P23: 13 | Q23: =IF(P23>=50,"High",IF(P23>=10,"Mid",IF(P23<10,"Low","invalid"))) -> Mid | R23: D56 | S23: S | T23: =IF(S23="Q","Queenstown",IF(S23="C","Cherbourg",IF(S23="S","Southampton","Unknown"))) -> Southampton
A24: 23 | B24: 1 | C24: 3 | D24: McGowan | E24: Anna "Annie" | F24: Miss | G24: =_xlfn.XLOOKUP(F24,notes!$B$12:$B$18,notes!$C$12:$C$18,"Unknown") -> Female | H24: 15 | I24: =_xlfn.XLOOKUP(H24,notes!$B$4:$B$8,notes!$C$4:$C$8,"Invalid",-1) -> Teenager | J24: 0 | K24: 0 | L24: =(J24+K24)+1 -> 1 | M24: =IF(B24=1,"Survived","Not Survived") -> Survived | N24: =_xlfn.XLOOKUP(L24,notes!$B$28:$B$30,notes!$C$28:$C$30,"Unknown",-1) -> Alone | O24: 330923 | P24: 8.0292 | Q24: =IF(P24>=50,"High",IF(P24>=10,"Mid",IF(P24<10,"Low","invalid"))) -> Low | R24: Unknown | S24: Q | T24: =IF(S24="Q","Queenstown",IF(S24="C","Cherbourg",IF(S24="S","Southampton","Unknown"))) -> Queenstown
A25: 24 | B25: 1 | C25: 1 | D25: Sloper | E25: William Thompson | F25: Mr | G25: =_xlfn.XLOOKUP(F25,notes!$B$12:$B$18,notes!$C$12:$C$18,"Unknown") -> Male | H25: 28 | I25: =_xlfn.XLOOKUP(H25,notes!$B$4:$B$8,notes!$C$4:$C$8,"Invalid",-1) -> Adult | J25: 0 | K25: 0 | L25: =(J25+K25)+1 -> 1 | M25: =IF(B25=1,"Survived","Not Survived") -> Survived | N25: =_xlfn.XLOOKUP(L25,notes!$B$28:$B$30,notes!$C$28:$C$30,"Unknown",-1) -> Alone | O25: 113788 | P25: 35.5 | Q25: =IF(P25>=50,"High",IF(P25>=10,"Mid",IF(P25<10,"Low","invalid"))) -> Mid | R25: A6 | S25: S | T25: =IF(S25="Q","Queenstown",IF(S25="C","Cherbourg",IF(S25="S","Southampton","Unknown"))) -> Southampton
A26: 25 | B26: 0 | C26: 3 | D26: Palsson | E26: Torborg Danira | F26: Miss | G26: =_xlfn.XLOOKUP(F26,notes!$B$12:$B$18,notes!$C$12:$C$18,"Unknown") -> Female | H26: 8 | I26: =_xlfn.XLOOKUP(H26,notes!$B$4:$B$8,notes!$C$4:$C$8,"Invalid",-1) -> Kid | J26: 3 | K26: 1 | L26: =(J26+K26)+1 -> 5 | M26: =IF(B26=1,"Survived","Not Survived") -> Not Survived | N26: =_xlfn.XLOOKUP(L26,notes!$B$28:$B$30,notes!$C$28:$C$30,"Unknown",-1) -> Large Family | O26: 349909 | P26: 21.075 | Q26: =IF(P26>=50,"High",IF(P26>=10,"Mid",IF(P26<10,"Low","invalid"))) -> Mid | R26: Unknown | S26: S | T26: =IF(S26="Q","Queenstown",IF(S26="C","Cherbourg",IF(S26="S","Southampton","Unknown"))) -> Southampton
A27: 26 | B27: 1 | C27: 3 | D27: Asplund | E27: Carl Oscar (Selma Augusta Emilia Johansson) | F27: Mrs | G27: =_xlfn.XLOOKUP(F27,notes!$B$12:$B$18,notes!$C$12:$C$18,"Unknown") -> Female | H27: 38 | I27: =_xlfn.XLOOKUP(H27,notes!$B$4:$B$8,notes!$C$4:$C$8,"Invalid",-1) -> Adult | J27: 1 | K27: 5 | L27: =(J27+K27)+1 -> 7 | M27: =IF(B27=1,"Survived","Not Survived") -> Survived | N27: =_xlfn.XLOOKUP(L27,notes!$B$28:$B$30,notes!$C$28:$C$30,"Unknown",-1) -> Large Family | O27: 347077 | P27: 31.3875 | Q27: =IF(P27>=50,"High",IF(P27>=10,"Mid",IF(P27<10,"Low","invalid"))) -> Mid | R27: Unknown | S27: S | T27: =IF(S27="Q","Queenstown",IF(S27="C","Cherbourg",IF(S27="S","Southampton","Unknown"))) -> Southampton
A28: 27 | B28: 0 | C28: 3 | D28: Emir | E28: Farred Chehab | F28: Mr | G28: =_xlfn.XLOOKUP(F28,notes!$B$12:$B$18,notes!$C$12:$C$18,"Unknown") -> Male | H28: Unknown | I28: =_xlfn.XLOOKUP(H28,notes!$B$4:$B$8,notes!$C$4:$C$8,"Invalid",-1) -> Unknown | J28: 0 | K28: 0 | L28: =(J28+K28)+1 -> 1 | M28: =IF(B28=1,"Survived","Not Survived") -> Not Survived | N28: =_xlfn.XLOOKUP(L28,notes!$B$28:$B$30,notes!$C$28:$C$30,"Unknown",-1) -> Alone | O28: 2631 | P28: 7.225 | Q28: =IF(P28>=50,"High",IF(P28>=10,"Mid",IF(P28<10,"Low","invalid"))) -> Low | R28: Unknown | S28: C | T28: =IF(S28="Q","Queenstown",IF(S28="C","Cherbourg",IF(S28="S","Southampton","Unknown"))) -> Cherbourg
A29: 28 | B29: 0 | C29: 1 | D29: Fortune | E29: Charles Alexander | F29: Mr | G29: =_xlfn.XLOOKUP(F29,notes!$B$12:$B$18,notes!$C$12:$C$18,"Unknown") -> Male | H29: 19 | I29: =_xlfn.XLOOKUP(H29,notes!$B$4:$B$8,notes!$C$4:$C$8,"Invalid",-1) -> Teenager | J29: 3 | K29: 2 | L29: =(J29+K29)+1 -> 6 | M29: =IF(B29=1,"Survived","Not Survived") -> Not Survived | N29: =_xlfn.XLOOKUP(L29,notes!$B$28:$B$30,notes!$C$28:$C$30,"Unknown",-1) -> Large Family | O29: 19950 | P29: 263 | Q29: =IF(P29>=50,"High",IF(P29>=10,"Mid",IF(P29<10,"Low","invalid"))) -> High | R29: C23 C25 C27 | S29: S | T29: =IF(S29="Q","Queenstown",IF(S29="C","Cherbourg",IF(S29="S","Southampton","Unknown"))) -> Southampton
A30: 29 | B30: 1 | C30: 3 | D30: O'Dwyer | E30: Ellen "Nellie" | F30: Miss | G30: =_xlfn.XLOOKUP(F30,notes!$B$12:$B$18,notes!$C$12:$C$18,"Unknown") -> Female | H30: Unknown | I30: =_xlfn.XLOOKUP(H30,notes!$B$4:$B$8,notes!$C$4:$C$8,"Invalid",-1) -> Unknown | J30: 0 | K30: 0 | L30: =(J30+K30)+1 -> 1 | M30: =IF(B30=1,"Survived","Not Survived") -> Survived | N30: =_xlfn.XLOOKUP(L30,notes!$B$28:$B$30,notes!$C$28:$C$30,"Unknown",-1) -> Alone | O30: 330959 | P30: 7.8792 | Q30: =IF(P30>=50,"High",IF(P30>=10,"Mid",IF(P30<10,"Low","invalid"))) -> Low | R30: Unknown | S30: Q | T30: =IF(S30="Q","Queenstown",IF(S30="C","Cherbourg",IF(S30="S","Southampton","Unknown"))) -> Queenstown
A31: 30 | B31: 0 | C31: 3 | D31: Todoroff | E31: Lalio | F31: Mr | G31: =_xlfn.XLOOKUP(F31,notes!$B$12:$B$18,notes!$C$12:$C$18,"Unknown") -> Male | H31: Unknown | I31: =_xlfn.XLOOKUP(H31,notes!$B$4:$B$8,notes!$C$4:$C$8,"Invalid",-1) -> Unknown | J31: 0 | K31: 0 | L31: =(J31+K31)+1 -> 1 | M31: =IF(B31=1,"Survived","Not Survived") -> Not Survived | N31: =_xlfn.XLOOKUP(L31,notes!$B$28:$B$30,notes!$C$28:$C$30,"Unknown",-1) -> Alone | O31: 349216 | P31: 7.8958 | Q31: =IF(P31>=50,"High",IF(P31>=10,"Mid",IF(P31<10,"Low","invalid"))) -> Low | R31: Unknown | S31: S | T31: =IF(S31="Q","Queenstown",IF(S31="C","Cherbourg",IF(S31="S","Southampton","Unknown"))) -> Southampton
A32: 31 | B32: 0 | C32: 1 | D32: Uruchurtu | E32: Manuel E | F32: Don | G32: =_xlfn.XLOOKUP(F32,notes!$B$12:$B$18,notes!$C$12:$C$18,"Unknown") -> Unknown | H32: 40 | I32: =_xlfn.XLOOKUP(H32,notes!$B$4:$B$8,notes!$C$4:$C$8,"Invalid",-1) -> Adult | J32: 0 | K32: 0 | L32: =(J32+K32)+1 -> 1 | M32: =IF(B32=1,"Survived","Not Survived") -> Not Survived | N32: =_xlfn.XLOOKUP(L32,notes!$B$28:$B$30,notes!$C$28:$C$30,"Unknown",-1) -> Alone | O32: PC 17601 | P32: 27.7208 | Q32: =IF(P32>=50,"High",IF(P32>=10,"Mid",IF(P32<10,"Low","invalid"))) -> Mid | R32: Unknown | S32: C | T32: =IF(S32="Q","Queenstown",IF(S32="C","Cherbourg",IF(S32="S","Southampton","Unknown"))) -> Cherbourg
A33: 32 | B33: 1 | C33: 1 | D33: Spencer | E33: William Augustus (Marie Eugenie) | F33: Mrs | G33: =_xlfn.XLOOKUP(F33,notes!$B$12:$B$18,notes!$C$12:$C$18,"Unknown") -> Female | H33: Unknown | I33: =_xlfn.XLOOKUP(H33,notes!$B$4:$B$8,notes!$C$4:$C$8,"Invalid",-1) -> Unknown | J33: 1 | K33: 0 | L33: =(J33+K33)+1 -> 2 | M33: =IF(B33=1,"Survived","Not Survived") -> Survived | N33: =_xlfn.XLOOKUP(L33,notes!$B$28:$B$30,notes!$C$28:$C$30,"Unknown",-1) -> Small Family | O33: PC 17569 | P33: 146.5208 | Q33: =IF(P33>=50,"High",IF(P33>=10,"Mid",IF(P33<10,"Low","invalid"))) -> High | R33: B78 | S33: C | T33: =IF(S33="Q","Queenstown",IF(S33="C","Cherbourg",IF(S33="S","Southampton","Unknown"))) -> Cherbourg
A34: 33 | B34: 1 | C34: 3 | D34: Glynn | E34: Mary Agatha | F34: Miss | G34: =_xlfn.XLOOKUP(F34,notes!$B$12:$B$18,notes!$C$12:$C$18,"Unknown") -> Female | H34: Unknown | I34: =_xlfn.XLOOKUP(H34,notes!$B$4:$B$8,notes!$C$4:$C$8,"Invalid",-1) -> Unknown | J34: 0 | K34: 0 | L34: =(J34+K34)+1 -> 1 | M34: =IF(B34=1,"Survived","Not Survived") -> Survived | N34: =_xlfn.XLOOKUP(L34,notes!$B$28:$B$30,notes!$C$28:$C$30,"Unknown",-1) -> Alone | O34: 335677 | P34: 7.75 | Q34: =IF(P34>=50,"High",IF(P34>=10,"Mid",IF(P34<10,"Low","invalid"))) -> Low | R34: Unknown | S34: Q | T34: =IF(S34="Q","Queenstown",IF(S34="C","Cherbourg",IF(S34="S","Southampton","Unknown"))) -> Queenstown
A35: 34 | B35: 0 | C35: 2 | D35: Wheadon | E35: Edward H | F35: Mr | G35: =_xlfn.XLOOKUP(F35,notes!$B$12:$B$18,notes!$C$12:$C$18,"Unknown") -> Male | H35: 66 | I35: =_xlfn.XLOOKUP(H35,notes!$B$4:$B$8,notes!$C$4:$C$8,"Invalid",-1) -> Elderly | J35: 0 | K35: 0 | L35: =(J35+K35)+1 -> 1 | M35: =IF(B35=1,"Survived","Not Survived") -> Not Survived | N35: =_xlfn.XLOOKUP(L35,notes!$B$28:$B$30,notes!$C$28:$C$30,"Unknown",-1) -> Alone | O35: C.A. 24579 | P35: 10.5 | Q35: =IF(P35>=50,"High",IF(P35>=10,"Mid",IF(P35<10,"Low","invalid"))) -> Mid | R35: Unknown | S35: S | T35: =IF(S35="Q","Queenstown",IF(S35="C","Cherbourg",IF(S35="S","Southampton","Unknown"))) -> Southampton
A36: 35 | B36: 0 | C36: 1 | D36: Meyer | E36: Edgar Joseph | F36: Mr | G36: =_xlfn.XLOOKUP(F36,notes!$B$12:$B$18,notes!$C$12:$C$18,"Unknown") -> Male | H36: 28 | I36: =_xlfn.XLOOKUP(H36,notes!$B$4:$B$8,notes!$C$4:$C$8,"Invalid",-1) -> Adult | J36: 1 | K36: 0 | L36: =(J36+K36)+1 -> 2 | M36: =IF(B36=1,"Survived","Not Survived") -> Not Survived | N36: =_xlfn.XLOOKUP(L36,notes!$B$28:$B$30,notes!$C$28:$C$30,"Unknown",-1) -> Small Family | O36: PC 17604 | P36: 82.1708 | Q36: =IF(P36>=50,"High",IF(P36>=10,"Mid",IF(P36<10,"Low","invalid"))) -> High | R36: Unknown | S36: C | T36: =IF(S36="Q","Queenstown",IF(S36="C","Cherbourg",IF(S36="S","Southampton","Unknown"))) -> Cherbourg
A37: 36 | B37: 0 | C37: 1 | D37: Holverson | E37: Alexander Oskar | F37: Mr | G37: =_xlfn.XLOOKUP(F37,notes!$B$12:$B$18,notes!$C$12:$C$18,"Unknown") -> Male | H37: 42 | I37: =_xlfn.XLOOKUP(H37,notes!$B$4:$B$8,notes!$C$4:$C$8,"Invalid",-1) -> Adult | J37: 1 | K37: 0 | L37: =(J37+K37)+1 -> 2 | M37: =IF(B37=1,"Survived","Not Survived") -> Not Survived | N37: =_xlfn.XLOOKUP(L37,notes!$B$28:$B$30,notes!$C$28:$C$30,"Unknown",-1) -> Small Family | O37: 113789 | P37: 52 | Q37: =IF(P37>=50,"High",IF(P37>=10,"Mid",IF(P37<10,"Low","invalid"))) -> High | R37: Unknown | S37: S | T37: =IF(S37="Q","Queenstown",IF(S37="C","Cherbourg",IF(S37="S","Southampton","Unknown"))) -> Southampton
A38: 37 | B38: 1 | C38: 3 | D38: Mamee | E38: Hanna | F38: Mr | G38: =_xlfn.XLOOKUP(F38,notes!$B$12:$B$18,notes!$C$12:$C$18,"Unknown") -> Male | H38: Unknown | I38: =_xlfn.XLOOKUP(H38,notes!$B$4:$B$8,notes!$C$4:$C$8,"Invalid",-1) -> Unknown | J38: 0 | K38: 0 | L38: =(J38+K38)+1 -> 1 | M38: =IF(B38=1,"Survived","Not Survived") -> Survived | N38: =_xlfn.XLOOKUP(L38,notes!$B$28:$B$30,notes!$C$28:$C$30,"Unknown",-1) -> Alone | O38: 2677 | P38: 7.2292 | Q38: =IF(P38>=50,"High",IF(P38>=10,"Mid",IF(P38<10,"Low","invalid"))) -> Low | R38: Unknown | S38: C | T38: =IF(S38="Q","Queenstown",IF(S38="C","Cherbourg",IF(S38="S","Southampton","Unknown"))) -> Cherbourg
A39: 38 | B39: 0 | C39: 3 | D39: Cann | E39: Ernest Charles | F39: Mr | G39: =_xlfn.XLOOKUP(F39,notes!$B$12:$B$18,notes!$C$12:$C$18,"Unknown") -> Male | H39: 21 | I39: =_xlfn.XLOOKUP(H39,notes!$B$4:$B$8,notes!$C$4:$C$8,"Invalid",-1) -> Adult | J39: 0 | K39: 0 | L39: =(J39+K39)+1 -> 1 | M39: =IF(B39=1,"Survived","Not Survived") -> Not Survived | N39: =_xlfn.XLOOKUP(L39,notes!$B$28:$B$30,notes!$C$28:$C$30,"Unknown",-1) -> Alone | O39: A./5. 2152 | P39: 8.05 | Q39: =IF(P39>=50,"High",IF(P39>=10,"Mid",IF(P39<10,"Low","invalid"))) -> Low | R39: Unknown | S39: S | T39: =IF(S39="Q","Queenstown",IF(S39="C","Cherbourg",IF(S39="S","Southampton","Unknown"))) -> Southampton
A40: 39 | B40: 0 | C40: 3 | D40: Vander Planke | E40: Augusta Maria | F40: Miss | G40: =_xlfn.XLOOKUP(F40,notes!$B$12:$B$18,notes!$C$12:$C$18,"Unknown") -> Female | H40: 18 | I40: =_xlfn.XLOOKUP(H40,notes!$B$4:$B$8,notes!$C$4:$C$8,"Invalid",-1) -> Teenager | J40: 2 | K40: 0 | L40: =(J40+K40)+1 -> 3 | M40: =IF(B40=1,"Survived","Not Survived") -> Not Survived | N40: =_xlfn.XLOOKUP(L40,notes!$B$28:$B$30,notes!$C$28:$C$30,"Unknown",-1) -> Small Family | O40: 345764 | P40: 18 | Q40: =IF(P40>=50,"High",IF(P40>=10,"Mid",IF(P40<10,"Low","invalid"))) -> Mid | R40: Unknown | S40: S | T40: =IF(S40="Q","Queenstown",IF(S40="C","Cherbourg",IF(S40="S","Southampton","Unknown"))) -> Southampton
...

Sheet Pivot Tables
A2: Survival Rate Based on Gender
A4: Gender | B4: Average of Survived
A5: Female | B5: 0.73615635
A6: Male | B6: 0.18881119
A7: Unknown | B7: 0.66666667
A8: Grand Total | B8: 0.38383838
A17: Survival Rate Based on Gender & Passenger Class
A19: Average of Survived | B19: Gender
A20: Pclass | B20: Female | C20: Male | D20: Unknown | E20: Grand Total
A21: 1 | B21: 0.96590909 | C21: 0.37606838 | D21: 0.63636364 | E21: 0.62962963
A22: 2 | B22: 0.92 | C22: 0.15740741 | D22: 1 | E22: 0.47282609
A23: 3 | B23: 0.5 | C23: 0.13544669 | E23: 0.24236253
A24: Grand Total | B24: 0.73615635 | C24: 0.18881119 | D24: 0.66666667 | E24: 0.38383838
A33: Survival Count By Family Size
A35: Count of Family_Size | B35: Survival_Status
A36: Family_Size | B36: Not Survived | C36: Survived | D36: Grand Total
A37: 1 | B37: 374 | C37: 163 | D37: 537
A38: 2 | B38: 72 | C38: 89 | D38: 161
A39: 3 | B39: 43 | C39: 59 | D39: 102
A40: 4 | B40: 8 | C40: 21 | D40: 29
A41: 5 | B41: 12 | C41: 3 | D41: 15
A42: 6 | B42: 19 | C42: 3 | D42: 22
A43: 7 | B43: 8 | C43: 4 | D43: 12
A44: 8 | B44: 6 | D44: 6
A45: 11 | B45: 7 | D45: 7
A46: Grand Total | B46: 549 | C46: 342 | D46: 891
A54: Passenger Count & Survival Rate by Age Group
A56: Age_Group | B56: Average of Survived | C56: Count of Age_Group
A57: Adult | B57: 0.38931298 | C57: 524
A58: Elderly | B58: 0.26923077 | C58: 26
A59: Kid | B59: 0.57971014 | C59: 69
A60: Teenager | B60: 0.41052632 | C60: 95
A61: Unknown | B61: 0.29378531 | C61: 177
A62: Grand Total | B62: 0.38383838 | C62: 891
A77: Survival Rate by Embarkation Point, Passenger Class & Gender
A80: Gender | B80: Female
A82: Average of Survived | B82: Pclass
A83: Embark_Point | B83: 1 | C83: 2 | D83: 3 | E83: Grand Total
A84: Cherbourg | B84: 0.97435897 | C84: 1 | D84: 0.65217391 | E84: 0.86956522
A85: Queenstown | B85: 1 | C85: 1 | D85: 0.72727273 | E85: 0.75
...

Sheet Dashboard
H2: Titanic Survival Dashboard
I6: Total Passengers 891 | M6: Overall Survival Rate 38%
I9: Key Insights: 1. Females had much higher survival rate than males. 2. First class passengers were most likely to survive. 3. Third class had lowest survival. 4. Embarkation point also influenced survival slightly.

Sheet notes
B2: Age Group
B3: Min Age | C3: Age Group | E3: Note:I grouped passenger into age bands using XLOOKUP with approximate matching.
B4: Unknown | C4: Unknown
B5: 0 | C5: Kid
B6: 13 | C6: Teenager
B7: 20 | C7: Adult
B8: 60 | C8: Elderly
B10: Gender
B11: Title | C11: Gender | E11: Note:I grouped passenger gender bands using XLOOKUP with approximate matching.
B12: Mr | C12: Male
B13: Mrs | C13: Female
B14: Miss | C14: Female
B15: Master | C15: Male
B16: Dr | C16: Male
B17: Col | C17: Male
B18: Rev | C18: Male
B20: Fare Fraction | E20: Note:I grouped passenger fares into Low, Mid, and High bands using XLOOKUP with approximate matching.
B21: Fare | C21: Range
B22: 0 | C22: Low
B23: 20 | C23: Mid
B24: 50 | C24: High
B26: Family Category | E26: Note:I grouped passenger family bands using XLOOKUP with approximate matching.
B27: Size | C27: Category
B28: 1 | C28: Alone
B29: 2 | C29: Small Family
B30: 4 | C30: Large Family
